

2025-05-19T13:20:24.331449 - Script policy_enforcer.py avviato
2025-05-19T13:20:24.334124 - ❌ Errore durante l'esecuzione:
2025-05-19T13:20:24.341652 - Traceback (most recent call last):
  File "/opt/splunk/etc/apps/my_custom_alerts/bin/scripts/policy_enforcer.py", line 25, in main
    payload = json.load(sys.stdin)
  File "/opt/splunk/lib/python3.9/json/__init__.py", line 293, in load
    return loads(fp.read(),
  File "/opt/splunk/lib/python3.9/json/__init__.py", line 346, in loads
    return _default_decoder.decode(s)
  File "/opt/splunk/lib/python3.9/json/decoder.py", line 337, in decode
    obj, end = self.raw_decode(s, idx=_w(s, 0).end())
  File "/opt/splunk/lib/python3.9/json/decoder.py", line 355, in raw_decode
    raise JSONDecodeError("Expecting value", s, err.value) from None
json.decoder.JSONDecodeError: Expecting value: line 1 column 1 (char 0)

2025-05-19T13:21:01.475635 - Script policy_enforcer.py avviato
2025-05-19T13:21:01.478976 - ❌ Errore durante l'esecuzione:
2025-05-19T13:21:01.488088 - Traceback (most recent call last):
  File "/opt/splunk/etc/apps/my_custom_alerts/bin/scripts/policy_enforcer.py", line 25, in main
    payload = json.load(sys.stdin)
  File "/opt/splunk/lib/python3.9/json/__init__.py", line 293, in load
    return loads(fp.read(),
  File "/opt/splunk/lib/python3.9/json/__init__.py", line 346, in loads
    return _default_decoder.decode(s)
  File "/opt/splunk/lib/python3.9/json/decoder.py", line 337, in decode
    obj, end = self.raw_decode(s, idx=_w(s, 0).end())
  File "/opt/splunk/lib/python3.9/json/decoder.py", line 355, in raw_decode
    raise JSONDecodeError("Expecting value", s, err.value) from None
json.decoder.JSONDecodeError: Expecting value: line 1 column 1 (char 0)

2025-05-19T13:22:00.890240 - Script policy_enforcer.py avviato
2025-05-19T13:22:00.893674 - ❌ Errore durante l'esecuzione:
2025-05-19T13:22:00.901014 - Traceback (most recent call last):
  File "/opt/splunk/etc/apps/my_custom_alerts/bin/scripts/policy_enforcer.py", line 25, in main
    payload = json.load(sys.stdin)
  File "/opt/splunk/lib/python3.9/json/__init__.py", line 293, in load
    return loads(fp.read(),
  File "/opt/splunk/lib/python3.9/json/__init__.py", line 346, in loads
    return _default_decoder.decode(s)
  File "/opt/splunk/lib/python3.9/json/decoder.py", line 337, in decode
    obj, end = self.raw_decode(s, idx=_w(s, 0).end())
  File "/opt/splunk/lib/python3.9/json/decoder.py", line 355, in raw_decode
    raise JSONDecodeError("Expecting value", s, err.value) from None
json.decoder.JSONDecodeError: Expecting value: line 1 column 1 (char 0)

2025-05-19T13:23:00.897505 - Script policy_enforcer.py avviato
2025-05-19T13:23:00.901752 - ❌ Errore durante l'esecuzione:
2025-05-19T13:23:00.914421 - Traceback (most recent call last):
  File "/opt/splunk/etc/apps/my_custom_alerts/bin/scripts/policy_enforcer.py", line 25, in main
    payload = json.load(sys.stdin)
  File "/opt/splunk/lib/python3.9/json/__init__.py", line 293, in load
    return loads(fp.read(),
  File "/opt/splunk/lib/python3.9/json/__init__.py", line 346, in loads
    return _default_decoder.decode(s)
  File "/opt/splunk/lib/python3.9/json/decoder.py", line 337, in decode
    obj, end = self.raw_decode(s, idx=_w(s, 0).end())
  File "/opt/splunk/lib/python3.9/json/decoder.py", line 355, in raw_decode
    raise JSONDecodeError("Expecting value", s, err.value) from None
json.decoder.JSONDecodeError: Expecting value: line 1 column 1 (char 0)

2025-05-19T13:24:01.085744 - Script policy_enforcer.py avviato
2025-05-19T13:24:01.089202 - ❌ Errore durante l'esecuzione:
2025-05-19T13:24:01.100258 - Traceback (most recent call last):
  File "/opt/splunk/etc/apps/my_custom_alerts/bin/scripts/policy_enforcer.py", line 25, in main
    payload = json.load(sys.stdin)
  File "/opt/splunk/lib/python3.9/json/__init__.py", line 293, in load
    return loads(fp.read(),
  File "/opt/splunk/lib/python3.9/json/__init__.py", line 346, in loads
    return _default_decoder.decode(s)
  File "/opt/splunk/lib/python3.9/json/decoder.py", line 337, in decode
    obj, end = self.raw_decode(s, idx=_w(s, 0).end())
  File "/opt/splunk/lib/python3.9/json/decoder.py", line 355, in raw_decode
    raise JSONDecodeError("Expecting value", s, err.value) from None
json.decoder.JSONDecodeError: Expecting value: line 1 column 1 (char 0)

2025-05-19T13:25:01.065922 - Script policy_enforcer.py avviato
2025-05-19T13:25:01.069232 - ❌ Errore durante l'esecuzione:
2025-05-19T13:25:01.080595 - Traceback (most recent call last):
  File "/opt/splunk/etc/apps/my_custom_alerts/bin/scripts/policy_enforcer.py", line 25, in main
    payload = json.load(sys.stdin)
  File "/opt/splunk/lib/python3.9/json/__init__.py", line 293, in load
    return loads(fp.read(),
  File "/opt/splunk/lib/python3.9/json/__init__.py", line 346, in loads
    return _default_decoder.decode(s)
  File "/opt/splunk/lib/python3.9/json/decoder.py", line 337, in decode
    obj, end = self.raw_decode(s, idx=_w(s, 0).end())
  File "/opt/splunk/lib/python3.9/json/decoder.py", line 355, in raw_decode
    raise JSONDecodeError("Expecting value", s, err.value) from None
json.decoder.JSONDecodeError: Expecting value: line 1 column 1 (char 0)

2025-05-19T13:26:01.077236 - Script policy_enforcer.py avviato
2025-05-19T13:26:01.081027 - ❌ Errore durante l'esecuzione:
2025-05-19T13:26:01.096682 - Traceback (most recent call last):
  File "/opt/splunk/etc/apps/my_custom_alerts/bin/scripts/policy_enforcer.py", line 25, in main
    payload = json.load(sys.stdin)
  File "/opt/splunk/lib/python3.9/json/__init__.py", line 293, in load
    return loads(fp.read(),
  File "/opt/splunk/lib/python3.9/json/__init__.py", line 346, in loads
    return _default_decoder.decode(s)
  File "/opt/splunk/lib/python3.9/json/decoder.py", line 337, in decode
    obj, end = self.raw_decode(s, idx=_w(s, 0).end())
  File "/opt/splunk/lib/python3.9/json/decoder.py", line 355, in raw_decode
    raise JSONDecodeError("Expecting value", s, err.value) from None
json.decoder.JSONDecodeError: Expecting value: line 1 column 1 (char 0)

2025-05-19T13:27:00.958668 - Script policy_enforcer.py avviato
2025-05-19T13:27:00.962370 - ❌ Errore durante l'esecuzione:
2025-05-19T13:27:00.973877 - Traceback (most recent call last):
  File "/opt/splunk/etc/apps/my_custom_alerts/bin/scripts/policy_enforcer.py", line 25, in main
    payload = json.load(sys.stdin)
  File "/opt/splunk/lib/python3.9/json/__init__.py", line 293, in load
    return loads(fp.read(),
  File "/opt/splunk/lib/python3.9/json/__init__.py", line 346, in loads
    return _default_decoder.decode(s)
  File "/opt/splunk/lib/python3.9/json/decoder.py", line 337, in decode
    obj, end = self.raw_decode(s, idx=_w(s, 0).end())
  File "/opt/splunk/lib/python3.9/json/decoder.py", line 355, in raw_decode
    raise JSONDecodeError("Expecting value", s, err.value) from None
json.decoder.JSONDecodeError: Expecting value: line 1 column 1 (char 0)

2025-05-19T13:28:00.950093 - Script policy_enforcer.py avviato
2025-05-19T13:28:00.953614 - ❌ Errore durante l'esecuzione:
2025-05-19T13:28:00.965223 - Traceback (most recent call last):
  File "/opt/splunk/etc/apps/my_custom_alerts/bin/scripts/policy_enforcer.py", line 25, in main
    payload = json.load(sys.stdin)
  File "/opt/splunk/lib/python3.9/json/__init__.py", line 293, in load
    return loads(fp.read(),
  File "/opt/splunk/lib/python3.9/json/__init__.py", line 346, in loads
    return _default_decoder.decode(s)
  File "/opt/splunk/lib/python3.9/json/decoder.py", line 337, in decode
    obj, end = self.raw_decode(s, idx=_w(s, 0).end())
  File "/opt/splunk/lib/python3.9/json/decoder.py", line 355, in raw_decode
    raise JSONDecodeError("Expecting value", s, err.value) from None
json.decoder.JSONDecodeError: Expecting value: line 1 column 1 (char 0)

2025-05-19T16:03:28.568614 - Script policy_enforcer.py avviato
2025-05-19T16:03:28.570880 - ❌ Errore durante l'esecuzione:
2025-05-19T16:03:28.578370 - Traceback (most recent call last):
  File "/opt/splunk/etc/apps/my_custom_alerts/bin/scripts/policy_enforcer.py", line 25, in main
    payload = json.load(sys.stdin)
  File "/opt/splunk/lib/python3.9/json/__init__.py", line 293, in load
    return loads(fp.read(),
  File "/opt/splunk/lib/python3.9/json/__init__.py", line 346, in loads
    return _default_decoder.decode(s)
  File "/opt/splunk/lib/python3.9/json/decoder.py", line 337, in decode
    obj, end = self.raw_decode(s, idx=_w(s, 0).end())
  File "/opt/splunk/lib/python3.9/json/decoder.py", line 355, in raw_decode
    raise JSONDecodeError("Expecting value", s, err.value) from None
json.decoder.JSONDecodeError: Expecting value: line 1 column 1 (char 0)

2025-05-19T16:04:01.408801 - Script policy_enforcer.py avviato
2025-05-19T16:04:01.412025 - ❌ Errore durante l'esecuzione:
2025-05-19T16:04:01.422135 - Traceback (most recent call last):
  File "/opt/splunk/etc/apps/my_custom_alerts/bin/scripts/policy_enforcer.py", line 25, in main
    payload = json.load(sys.stdin)
  File "/opt/splunk/lib/python3.9/json/__init__.py", line 293, in load
    return loads(fp.read(),
  File "/opt/splunk/lib/python3.9/json/__init__.py", line 346, in loads
    return _default_decoder.decode(s)
  File "/opt/splunk/lib/python3.9/json/decoder.py", line 337, in decode
    obj, end = self.raw_decode(s, idx=_w(s, 0).end())
  File "/opt/splunk/lib/python3.9/json/decoder.py", line 355, in raw_decode
    raise JSONDecodeError("Expecting value", s, err.value) from None
json.decoder.JSONDecodeError: Expecting value: line 1 column 1 (char 0)

2025-05-19T16:05:01.249990 - Script policy_enforcer.py avviato
2025-05-19T16:05:01.253572 - ❌ Errore durante l'esecuzione:
2025-05-19T16:05:01.264182 - Traceback (most recent call last):
  File "/opt/splunk/etc/apps/my_custom_alerts/bin/scripts/policy_enforcer.py", line 25, in main
    payload = json.load(sys.stdin)
  File "/opt/splunk/lib/python3.9/json/__init__.py", line 293, in load
    return loads(fp.read(),
  File "/opt/splunk/lib/python3.9/json/__init__.py", line 346, in loads
    return _default_decoder.decode(s)
  File "/opt/splunk/lib/python3.9/json/decoder.py", line 337, in decode
    obj, end = self.raw_decode(s, idx=_w(s, 0).end())
  File "/opt/splunk/lib/python3.9/json/decoder.py", line 355, in raw_decode
    raise JSONDecodeError("Expecting value", s, err.value) from None
json.decoder.JSONDecodeError: Expecting value: line 1 column 1 (char 0)

2025-05-19T16:06:01.219522 - Script policy_enforcer.py avviato
2025-05-19T16:06:01.222713 - ❌ Errore durante l'esecuzione:
2025-05-19T16:06:01.231611 - Traceback (most recent call last):
  File "/opt/splunk/etc/apps/my_custom_alerts/bin/scripts/policy_enforcer.py", line 25, in main
    payload = json.load(sys.stdin)
  File "/opt/splunk/lib/python3.9/json/__init__.py", line 293, in load
    return loads(fp.read(),
  File "/opt/splunk/lib/python3.9/json/__init__.py", line 346, in loads
    return _default_decoder.decode(s)
  File "/opt/splunk/lib/python3.9/json/decoder.py", line 337, in decode
    obj, end = self.raw_decode(s, idx=_w(s, 0).end())
  File "/opt/splunk/lib/python3.9/json/decoder.py", line 355, in raw_decode
    raise JSONDecodeError("Expecting value", s, err.value) from None
json.decoder.JSONDecodeError: Expecting value: line 1 column 1 (char 0)

2025-05-19T16:07:01.195573 - Script policy_enforcer.py avviato
2025-05-19T16:07:01.198739 - Raw stdin ricevuto: sessionKey=_QnKsYpROulvJ%5EF7SDoeTFSg0utF3TInHZTwst7EozqsHmjMLGCmMonA7dU6wGx7%5ES90PiHSkhoGx8dRmkQ39DpvJuo3V8%5EHT_1T5Hfrk8SJUj7FPZASPeRTa9ZKJrpPYaYuFQD4V18ld5EeSBVUpFYb

2025-05-19T16:07:01.201291 - ❌ Errore durante l'esecuzione:
2025-05-19T16:07:01.208898 - Traceback (most recent call last):
  File "/opt/splunk/etc/apps/my_custom_alerts/bin/scripts/policy_enforcer.py", line 28, in main
    payload = json.load(sys.stdin)
  File "/opt/splunk/lib/python3.9/json/__init__.py", line 293, in load
    return loads(fp.read(),
  File "/opt/splunk/lib/python3.9/json/__init__.py", line 346, in loads
    return _default_decoder.decode(s)
  File "/opt/splunk/lib/python3.9/json/decoder.py", line 337, in decode
    obj, end = self.raw_decode(s, idx=_w(s, 0).end())
  File "/opt/splunk/lib/python3.9/json/decoder.py", line 355, in raw_decode
    raise JSONDecodeError("Expecting value", s, err.value) from None
json.decoder.JSONDecodeError: Expecting value: line 1 column 1 (char 0)

2025-05-19T16:08:01.492531 - Script policy_enforcer.py avviato
2025-05-19T16:08:01.494839 - Raw stdin ricevuto: sessionKey=edD4lgjgj3iyvOZQpcu300M%5ES6vMUX3LE_eaG1nX7smFp8lRpvY7ghn6u6HX0pdlHS1QV8QQCFTrakf4TN3dRyNP6lIcNcDViN9hnvzsVOMpXBWS54LNCTh2SQN9614fJudKBYENb2H_llYX6v5k41L9xNocYF

2025-05-19T16:08:01.496965 - ❌ Errore durante l'esecuzione:
2025-05-19T16:08:01.504383 - Traceback (most recent call last):
  File "/opt/splunk/etc/apps/my_custom_alerts/bin/scripts/policy_enforcer.py", line 28, in main
    payload = json.load(sys.stdin)
  File "/opt/splunk/lib/python3.9/json/__init__.py", line 293, in load
    return loads(fp.read(),
  File "/opt/splunk/lib/python3.9/json/__init__.py", line 346, in loads
    return _default_decoder.decode(s)
  File "/opt/splunk/lib/python3.9/json/decoder.py", line 337, in decode
    obj, end = self.raw_decode(s, idx=_w(s, 0).end())
  File "/opt/splunk/lib/python3.9/json/decoder.py", line 355, in raw_decode
    raise JSONDecodeError("Expecting value", s, err.value) from None
json.decoder.JSONDecodeError: Expecting value: line 1 column 1 (char 0)

2025-05-19T16:09:01.354804 - Script policy_enforcer.py avviato
2025-05-19T16:09:01.357335 - ❌ Errore di parsing JSON: Expecting value: line 1 column 1 (char 0)
2025-05-19T16:10:01.378699 - Script policy_enforcer.py avviato
2025-05-19T16:10:01.388871 - ❌ Errore di parsing JSON: Expecting value: line 1 column 1 (char 0)
2025-05-19T16:12:29.030273 - Script policy_enforcer.py avviato
2025-05-19T16:12:29.033493 - ❌ Errore di parsing JSON: Expecting value: line 1 column 1 (char 0)
2025-05-19T16:13:01.161607 - Script policy_enforcer.py avviato
2025-05-19T16:13:01.165404 - ❌ Errore di parsing JSON: Expecting value: line 1 column 1 (char 0)
2025-05-19T16:14:00.807972 - Script policy_enforcer.py avviato
2025-05-19T16:14:00.811076 - ❌ Errore di parsing JSON: Expecting value: line 1 column 1 (char 0)
2025-05-19T16:14:34.110243 - Script policy_enforcer.py avviato
2025-05-19T16:14:34.112919 - Payload ricevuto da Splunk:
2025-05-19T16:14:34.116007 - {
  "result": {
    "src_ip": "1.2.3.4"
  }
}
2025-05-19T16:14:38.126009 - ❌ Errore durante l'esecuzione:
2025-05-19T16:14:38.136176 - Traceback (most recent call last):
  File "/usr/lib/python3.9/site-packages/urllib3/connection.py", line 174, in _new_conn
    conn = connection.create_connection(
  File "/usr/lib/python3.9/site-packages/urllib3/util/connection.py", line 72, in create_connection
    for res in socket.getaddrinfo(host, port, family, socket.SOCK_STREAM):
  File "/usr/lib/python3.9/socket.py", line 954, in getaddrinfo
    for res in _socket.getaddrinfo(host, port, family, type, proto, flags):
socket.gaierror: [Errno -2] Name or service not known

During handling of the above exception, another exception occurred:

Traceback (most recent call last):
  File "/usr/lib/python3.9/site-packages/urllib3/connectionpool.py", line 716, in urlopen
    httplib_response = self._make_request(
  File "/usr/lib/python3.9/site-packages/urllib3/connectionpool.py", line 416, in _make_request
    conn.request(method, url, **httplib_request_kw)
  File "/usr/lib/python3.9/site-packages/urllib3/connection.py", line 244, in request
    super(HTTPConnection, self).request(method, url, body=body, headers=headers)
  File "/usr/lib/python3.9/http/client.py", line 1285, in request
    self._send_request(method, url, body, headers, encode_chunked)
  File "/usr/lib/python3.9/http/client.py", line 1331, in _send_request
    self.endheaders(body, encode_chunked=encode_chunked)
  File "/usr/lib/python3.9/http/client.py", line 1280, in endheaders
    self._send_output(message_body, encode_chunked=encode_chunked)
  File "/usr/lib/python3.9/http/client.py", line 1040, in _send_output
    self.send(msg)
  File "/usr/lib/python3.9/http/client.py", line 980, in send
    self.connect()
  File "/usr/lib/python3.9/site-packages/urllib3/connection.py", line 205, in connect
    conn = self._new_conn()
  File "/usr/lib/python3.9/site-packages/urllib3/connection.py", line 186, in _new_conn
    raise NewConnectionError(
urllib3.exceptions.NewConnectionError: <urllib3.connection.HTTPConnection object at 0x7fc1338a20d0>: Failed to establish a new connection: [Errno -2] Name or service not known

During handling of the above exception, another exception occurred:

Traceback (most recent call last):
  File "/usr/lib/python3.9/site-packages/requests/adapters.py", line 667, in send
    resp = conn.urlopen(
  File "/usr/lib/python3.9/site-packages/urllib3/connectionpool.py", line 802, in urlopen
    retries = retries.increment(
  File "/usr/lib/python3.9/site-packages/urllib3/util/retry.py", line 594, in increment
    raise MaxRetryError(_pool, url, error or ResponseError(cause))
urllib3.exceptions.MaxRetryError: HTTPConnectionPool(host='router', port=5000): Max retries exceeded with url: /enforce (Caused by NewConnectionError('<urllib3.connection.HTTPConnection object at 0x7fc1338a20d0>: Failed to establish a new connection: [Errno -2] Name or service not known'))

During handling of the above exception, another exception occurred:

Traceback (most recent call last):
  File "/opt/splunk/etc/apps/my_custom_alerts/bin/scripts/policy_enforcer.py", line 53, in main
    response = requests.post(FLASK_URL, json=alert_data)
  File "/usr/lib/python3.9/site-packages/requests/api.py", line 115, in post
    return request("post", url, data=data, json=json, **kwargs)
  File "/usr/lib/python3.9/site-packages/requests/api.py", line 59, in request
    return session.request(method=method, url=url, **kwargs)
  File "/usr/lib/python3.9/site-packages/requests/sessions.py", line 589, in request
    resp = self.send(prep, **send_kwargs)
  File "/usr/lib/python3.9/site-packages/requests/sessions.py", line 703, in send
    r = adapter.send(request, **kwargs)
  File "/usr/lib/python3.9/site-packages/requests/adapters.py", line 700, in send
    raise ConnectionError(e, request=request)
requests.exceptions.ConnectionError: HTTPConnectionPool(host='router', port=5000): Max retries exceeded with url: /enforce (Caused by NewConnectionError('<urllib3.connection.HTTPConnection object at 0x7fc1338a20d0>: Failed to establish a new connection: [Errno -2] Name or service not known'))

2025-05-19T16:14:42.400387 - Script policy_enforcer.py avviato
2025-05-19T16:14:42.403368 - Payload ricevuto da Splunk:
2025-05-19T16:14:42.406465 - {
  "result": {
    "src_ip": "1.2.3.4"
  }
}
2025-05-19T16:14:46.412789 - ❌ Errore durante l'esecuzione:
2025-05-19T16:14:46.423697 - Traceback (most recent call last):
  File "/usr/lib/python3.9/site-packages/urllib3/connection.py", line 174, in _new_conn
    conn = connection.create_connection(
  File "/usr/lib/python3.9/site-packages/urllib3/util/connection.py", line 72, in create_connection
    for res in socket.getaddrinfo(host, port, family, socket.SOCK_STREAM):
  File "/usr/lib/python3.9/socket.py", line 954, in getaddrinfo
    for res in _socket.getaddrinfo(host, port, family, type, proto, flags):
socket.gaierror: [Errno -2] Name or service not known

During handling of the above exception, another exception occurred:

Traceback (most recent call last):
  File "/usr/lib/python3.9/site-packages/urllib3/connectionpool.py", line 716, in urlopen
    httplib_response = self._make_request(
  File "/usr/lib/python3.9/site-packages/urllib3/connectionpool.py", line 416, in _make_request
    conn.request(method, url, **httplib_request_kw)
  File "/usr/lib/python3.9/site-packages/urllib3/connection.py", line 244, in request
    super(HTTPConnection, self).request(method, url, body=body, headers=headers)
  File "/usr/lib/python3.9/http/client.py", line 1285, in request
    self._send_request(method, url, body, headers, encode_chunked)
  File "/usr/lib/python3.9/http/client.py", line 1331, in _send_request
    self.endheaders(body, encode_chunked=encode_chunked)
  File "/usr/lib/python3.9/http/client.py", line 1280, in endheaders
    self._send_output(message_body, encode_chunked=encode_chunked)
  File "/usr/lib/python3.9/http/client.py", line 1040, in _send_output
    self.send(msg)
  File "/usr/lib/python3.9/http/client.py", line 980, in send
    self.connect()
  File "/usr/lib/python3.9/site-packages/urllib3/connection.py", line 205, in connect
    conn = self._new_conn()
  File "/usr/lib/python3.9/site-packages/urllib3/connection.py", line 186, in _new_conn
    raise NewConnectionError(
urllib3.exceptions.NewConnectionError: <urllib3.connection.HTTPConnection object at 0x7f066a2c20d0>: Failed to establish a new connection: [Errno -2] Name or service not known

During handling of the above exception, another exception occurred:

Traceback (most recent call last):
  File "/usr/lib/python3.9/site-packages/requests/adapters.py", line 667, in send
    resp = conn.urlopen(
  File "/usr/lib/python3.9/site-packages/urllib3/connectionpool.py", line 802, in urlopen
    retries = retries.increment(
  File "/usr/lib/python3.9/site-packages/urllib3/util/retry.py", line 594, in increment
    raise MaxRetryError(_pool, url, error or ResponseError(cause))
urllib3.exceptions.MaxRetryError: HTTPConnectionPool(host='router', port=5000): Max retries exceeded with url: /enforce (Caused by NewConnectionError('<urllib3.connection.HTTPConnection object at 0x7f066a2c20d0>: Failed to establish a new connection: [Errno -2] Name or service not known'))

During handling of the above exception, another exception occurred:

Traceback (most recent call last):
  File "/opt/splunk/etc/apps/my_custom_alerts/bin/scripts/policy_enforcer.py", line 53, in main
    response = requests.post(FLASK_URL, json=alert_data)
  File "/usr/lib/python3.9/site-packages/requests/api.py", line 115, in post
    return request("post", url, data=data, json=json, **kwargs)
  File "/usr/lib/python3.9/site-packages/requests/api.py", line 59, in request
    return session.request(method=method, url=url, **kwargs)
  File "/usr/lib/python3.9/site-packages/requests/sessions.py", line 589, in request
    resp = self.send(prep, **send_kwargs)
  File "/usr/lib/python3.9/site-packages/requests/sessions.py", line 703, in send
    r = adapter.send(request, **kwargs)
  File "/usr/lib/python3.9/site-packages/requests/adapters.py", line 700, in send
    raise ConnectionError(e, request=request)
requests.exceptions.ConnectionError: HTTPConnectionPool(host='router', port=5000): Max retries exceeded with url: /enforce (Caused by NewConnectionError('<urllib3.connection.HTTPConnection object at 0x7f066a2c20d0>: Failed to establish a new connection: [Errno -2] Name or service not known'))

2025-05-19T16:15:00.744924 - Script policy_enforcer.py avviato
2025-05-19T16:15:00.747962 - ❌ Errore di parsing JSON: Expecting value: line 1 column 1 (char 0)
2025-05-19T16:15:29.810482 - Script policy_enforcer.py avviato
2025-05-19T16:15:29.813757 - Payload ricevuto da Splunk:
2025-05-19T16:15:29.816926 - {
  "result": {
    "src_ip": "1.2.3.4"
  }
}
2025-05-19T16:15:33.830995 - ❌ Errore durante l'esecuzione:
2025-05-19T16:15:33.842755 - Traceback (most recent call last):
  File "/usr/lib/python3.9/site-packages/urllib3/connection.py", line 174, in _new_conn
    conn = connection.create_connection(
  File "/usr/lib/python3.9/site-packages/urllib3/util/connection.py", line 72, in create_connection
    for res in socket.getaddrinfo(host, port, family, socket.SOCK_STREAM):
  File "/usr/lib/python3.9/socket.py", line 954, in getaddrinfo
    for res in _socket.getaddrinfo(host, port, family, type, proto, flags):
socket.gaierror: [Errno -2] Name or service not known

During handling of the above exception, another exception occurred:

Traceback (most recent call last):
  File "/usr/lib/python3.9/site-packages/urllib3/connectionpool.py", line 716, in urlopen
    httplib_response = self._make_request(
  File "/usr/lib/python3.9/site-packages/urllib3/connectionpool.py", line 416, in _make_request
    conn.request(method, url, **httplib_request_kw)
  File "/usr/lib/python3.9/site-packages/urllib3/connection.py", line 244, in request
    super(HTTPConnection, self).request(method, url, body=body, headers=headers)
  File "/usr/lib/python3.9/http/client.py", line 1285, in request
    self._send_request(method, url, body, headers, encode_chunked)
  File "/usr/lib/python3.9/http/client.py", line 1331, in _send_request
    self.endheaders(body, encode_chunked=encode_chunked)
  File "/usr/lib/python3.9/http/client.py", line 1280, in endheaders
    self._send_output(message_body, encode_chunked=encode_chunked)
  File "/usr/lib/python3.9/http/client.py", line 1040, in _send_output
    self.send(msg)
  File "/usr/lib/python3.9/http/client.py", line 980, in send
    self.connect()
  File "/usr/lib/python3.9/site-packages/urllib3/connection.py", line 205, in connect
    conn = self._new_conn()
  File "/usr/lib/python3.9/site-packages/urllib3/connection.py", line 186, in _new_conn
    raise NewConnectionError(
urllib3.exceptions.NewConnectionError: <urllib3.connection.HTTPConnection object at 0x7f72e26a80d0>: Failed to establish a new connection: [Errno -2] Name or service not known

During handling of the above exception, another exception occurred:

Traceback (most recent call last):
  File "/usr/lib/python3.9/site-packages/requests/adapters.py", line 667, in send
    resp = conn.urlopen(
  File "/usr/lib/python3.9/site-packages/urllib3/connectionpool.py", line 802, in urlopen
    retries = retries.increment(
  File "/usr/lib/python3.9/site-packages/urllib3/util/retry.py", line 594, in increment
    raise MaxRetryError(_pool, url, error or ResponseError(cause))
urllib3.exceptions.MaxRetryError: HTTPConnectionPool(host='router', port=5000): Max retries exceeded with url: /enforce (Caused by NewConnectionError('<urllib3.connection.HTTPConnection object at 0x7f72e26a80d0>: Failed to establish a new connection: [Errno -2] Name or service not known'))

During handling of the above exception, another exception occurred:

Traceback (most recent call last):
  File "/opt/splunk/etc/apps/my_custom_alerts/bin/scripts/policy_enforcer.py", line 53, in main
    response = requests.post(FLASK_URL, json=alert_data)
  File "/usr/lib/python3.9/site-packages/requests/api.py", line 115, in post
    return request("post", url, data=data, json=json, **kwargs)
  File "/usr/lib/python3.9/site-packages/requests/api.py", line 59, in request
    return session.request(method=method, url=url, **kwargs)
  File "/usr/lib/python3.9/site-packages/requests/sessions.py", line 589, in request
    resp = self.send(prep, **send_kwargs)
  File "/usr/lib/python3.9/site-packages/requests/sessions.py", line 703, in send
    r = adapter.send(request, **kwargs)
  File "/usr/lib/python3.9/site-packages/requests/adapters.py", line 700, in send
    raise ConnectionError(e, request=request)
requests.exceptions.ConnectionError: HTTPConnectionPool(host='router', port=5000): Max retries exceeded with url: /enforce (Caused by NewConnectionError('<urllib3.connection.HTTPConnection object at 0x7f72e26a80d0>: Failed to establish a new connection: [Errno -2] Name or service not known'))

2025-05-19T16:16:00.844669 - Script policy_enforcer.py avviato
2025-05-19T16:16:00.848012 - ❌ Errore di parsing JSON: Expecting value: line 1 column 1 (char 0)
2025-05-19T16:17:01.612123 - Script policy_enforcer.py avviato
2025-05-19T16:17:01.617681 - ❌ Errore di parsing JSON: Expecting value: line 1 column 1 (char 0)
2025-05-19T16:17:38.080599 - Script policy_enforcer.py avviato
2025-05-19T16:17:38.083740 - Payload ricevuto da Splunk:
2025-05-19T16:17:38.087174 - {
  "result": {
    "src_ip": "1.2.3.4"
  }
}
2025-05-19T16:17:41.213918 - ❌ Errore durante l'esecuzione:
2025-05-19T16:17:41.222223 - Traceback (most recent call last):
  File "/usr/lib/python3.9/site-packages/urllib3/connection.py", line 174, in _new_conn
    conn = connection.create_connection(
  File "/usr/lib/python3.9/site-packages/urllib3/util/connection.py", line 95, in create_connection
    raise err
  File "/usr/lib/python3.9/site-packages/urllib3/util/connection.py", line 85, in create_connection
    sock.connect(sa)
OSError: [Errno 113] No route to host

During handling of the above exception, another exception occurred:

Traceback (most recent call last):
  File "/usr/lib/python3.9/site-packages/urllib3/connectionpool.py", line 716, in urlopen
    httplib_response = self._make_request(
  File "/usr/lib/python3.9/site-packages/urllib3/connectionpool.py", line 416, in _make_request
    conn.request(method, url, **httplib_request_kw)
  File "/usr/lib/python3.9/site-packages/urllib3/connection.py", line 244, in request
    super(HTTPConnection, self).request(method, url, body=body, headers=headers)
  File "/usr/lib/python3.9/http/client.py", line 1285, in request
    self._send_request(method, url, body, headers, encode_chunked)
  File "/usr/lib/python3.9/http/client.py", line 1331, in _send_request
    self.endheaders(body, encode_chunked=encode_chunked)
  File "/usr/lib/python3.9/http/client.py", line 1280, in endheaders
    self._send_output(message_body, encode_chunked=encode_chunked)
  File "/usr/lib/python3.9/http/client.py", line 1040, in _send_output
    self.send(msg)
  File "/usr/lib/python3.9/http/client.py", line 980, in send
    self.connect()
  File "/usr/lib/python3.9/site-packages/urllib3/connection.py", line 205, in connect
    conn = self._new_conn()
  File "/usr/lib/python3.9/site-packages/urllib3/connection.py", line 186, in _new_conn
    raise NewConnectionError(
urllib3.exceptions.NewConnectionError: <urllib3.connection.HTTPConnection object at 0x7f7c681750d0>: Failed to establish a new connection: [Errno 113] No route to host

During handling of the above exception, another exception occurred:

Traceback (most recent call last):
  File "/usr/lib/python3.9/site-packages/requests/adapters.py", line 667, in send
    resp = conn.urlopen(
  File "/usr/lib/python3.9/site-packages/urllib3/connectionpool.py", line 802, in urlopen
    retries = retries.increment(
  File "/usr/lib/python3.9/site-packages/urllib3/util/retry.py", line 594, in increment
    raise MaxRetryError(_pool, url, error or ResponseError(cause))
urllib3.exceptions.MaxRetryError: HTTPConnectionPool(host='192.168.200.254', port=5000): Max retries exceeded with url: /enforce (Caused by NewConnectionError('<urllib3.connection.HTTPConnection object at 0x7f7c681750d0>: Failed to establish a new connection: [Errno 113] No route to host'))

During handling of the above exception, another exception occurred:

Traceback (most recent call last):
  File "/opt/splunk/etc/apps/my_custom_alerts/bin/scripts/policy_enforcer.py", line 53, in main
    response = requests.post(FLASK_URL, json=alert_data)
  File "/usr/lib/python3.9/site-packages/requests/api.py", line 115, in post
    return request("post", url, data=data, json=json, **kwargs)
  File "/usr/lib/python3.9/site-packages/requests/api.py", line 59, in request
    return session.request(method=method, url=url, **kwargs)
  File "/usr/lib/python3.9/site-packages/requests/sessions.py", line 589, in request
    resp = self.send(prep, **send_kwargs)
  File "/usr/lib/python3.9/site-packages/requests/sessions.py", line 703, in send
    r = adapter.send(request, **kwargs)
  File "/usr/lib/python3.9/site-packages/requests/adapters.py", line 700, in send
    raise ConnectionError(e, request=request)
requests.exceptions.ConnectionError: HTTPConnectionPool(host='192.168.200.254', port=5000): Max retries exceeded with url: /enforce (Caused by NewConnectionError('<urllib3.connection.HTTPConnection object at 0x7f7c681750d0>: Failed to establish a new connection: [Errno 113] No route to host'))

2025-05-19T16:18:01.204355 - Script policy_enforcer.py avviato
2025-05-19T16:18:01.207710 - ❌ Errore di parsing JSON: Expecting value: line 1 column 1 (char 0)
2025-05-19T16:20:01.012921 - Script policy_enforcer.py avviato
2025-05-19T16:20:01.016589 - ❌ Errore di parsing JSON: Expecting value: line 1 column 1 (char 0)
2025-05-19T16:20:21.995285 - Script policy_enforcer.py avviato
2025-05-19T16:20:21.998785 - Payload ricevuto da Splunk:
2025-05-19T16:20:22.001782 - {
  "result": {
    "src_ip": "1.2.3.4"
  }
}
2025-05-19T16:20:25.123812 - ❌ Errore durante l'esecuzione:
2025-05-19T16:20:25.137386 - Traceback (most recent call last):
  File "/usr/lib/python3.9/site-packages/urllib3/connection.py", line 174, in _new_conn
    conn = connection.create_connection(
  File "/usr/lib/python3.9/site-packages/urllib3/util/connection.py", line 95, in create_connection
    raise err
  File "/usr/lib/python3.9/site-packages/urllib3/util/connection.py", line 85, in create_connection
    sock.connect(sa)
OSError: [Errno 113] No route to host

During handling of the above exception, another exception occurred:

Traceback (most recent call last):
  File "/usr/lib/python3.9/site-packages/urllib3/connectionpool.py", line 716, in urlopen
    httplib_response = self._make_request(
  File "/usr/lib/python3.9/site-packages/urllib3/connectionpool.py", line 416, in _make_request
    conn.request(method, url, **httplib_request_kw)
  File "/usr/lib/python3.9/site-packages/urllib3/connection.py", line 244, in request
    super(HTTPConnection, self).request(method, url, body=body, headers=headers)
  File "/usr/lib/python3.9/http/client.py", line 1285, in request
    self._send_request(method, url, body, headers, encode_chunked)
  File "/usr/lib/python3.9/http/client.py", line 1331, in _send_request
    self.endheaders(body, encode_chunked=encode_chunked)
  File "/usr/lib/python3.9/http/client.py", line 1280, in endheaders
    self._send_output(message_body, encode_chunked=encode_chunked)
  File "/usr/lib/python3.9/http/client.py", line 1040, in _send_output
    self.send(msg)
  File "/usr/lib/python3.9/http/client.py", line 980, in send
    self.connect()
  File "/usr/lib/python3.9/site-packages/urllib3/connection.py", line 205, in connect
    conn = self._new_conn()
  File "/usr/lib/python3.9/site-packages/urllib3/connection.py", line 186, in _new_conn
    raise NewConnectionError(
urllib3.exceptions.NewConnectionError: <urllib3.connection.HTTPConnection object at 0x7f82685760d0>: Failed to establish a new connection: [Errno 113] No route to host

During handling of the above exception, another exception occurred:

Traceback (most recent call last):
  File "/usr/lib/python3.9/site-packages/requests/adapters.py", line 667, in send
    resp = conn.urlopen(
  File "/usr/lib/python3.9/site-packages/urllib3/connectionpool.py", line 802, in urlopen
    retries = retries.increment(
  File "/usr/lib/python3.9/site-packages/urllib3/util/retry.py", line 594, in increment
    raise MaxRetryError(_pool, url, error or ResponseError(cause))
urllib3.exceptions.MaxRetryError: HTTPConnectionPool(host='192.168.200.254', port=5000): Max retries exceeded with url: /enforce (Caused by NewConnectionError('<urllib3.connection.HTTPConnection object at 0x7f82685760d0>: Failed to establish a new connection: [Errno 113] No route to host'))

During handling of the above exception, another exception occurred:

Traceback (most recent call last):
  File "/opt/splunk/etc/apps/my_custom_alerts/bin/scripts/policy_enforcer.py", line 53, in main
    response = requests.post(FLASK_URL, json=alert_data)
  File "/usr/lib/python3.9/site-packages/requests/api.py", line 115, in post
    return request("post", url, data=data, json=json, **kwargs)
  File "/usr/lib/python3.9/site-packages/requests/api.py", line 59, in request
    return session.request(method=method, url=url, **kwargs)
  File "/usr/lib/python3.9/site-packages/requests/sessions.py", line 589, in request
    resp = self.send(prep, **send_kwargs)
  File "/usr/lib/python3.9/site-packages/requests/sessions.py", line 703, in send
    r = adapter.send(request, **kwargs)
  File "/usr/lib/python3.9/site-packages/requests/adapters.py", line 700, in send
    raise ConnectionError(e, request=request)
requests.exceptions.ConnectionError: HTTPConnectionPool(host='192.168.200.254', port=5000): Max retries exceeded with url: /enforce (Caused by NewConnectionError('<urllib3.connection.HTTPConnection object at 0x7f82685760d0>: Failed to establish a new connection: [Errno 113] No route to host'))

2025-05-19T16:20:48.916390 - Script policy_enforcer.py avviato
2025-05-19T16:20:48.919064 - Payload ricevuto da Splunk:
2025-05-19T16:20:48.922722 - {
  "result": {
    "src_ip": "1.2.3.4"
  }
}
2025-05-19T16:20:52.082122 - ❌ Errore durante l'esecuzione:
2025-05-19T16:20:52.095476 - Traceback (most recent call last):
  File "/usr/lib/python3.9/site-packages/urllib3/connection.py", line 174, in _new_conn
    conn = connection.create_connection(
  File "/usr/lib/python3.9/site-packages/urllib3/util/connection.py", line 95, in create_connection
    raise err
  File "/usr/lib/python3.9/site-packages/urllib3/util/connection.py", line 85, in create_connection
    sock.connect(sa)
OSError: [Errno 113] No route to host

During handling of the above exception, another exception occurred:

Traceback (most recent call last):
  File "/usr/lib/python3.9/site-packages/urllib3/connectionpool.py", line 716, in urlopen
    httplib_response = self._make_request(
  File "/usr/lib/python3.9/site-packages/urllib3/connectionpool.py", line 416, in _make_request
    conn.request(method, url, **httplib_request_kw)
  File "/usr/lib/python3.9/site-packages/urllib3/connection.py", line 244, in request
    super(HTTPConnection, self).request(method, url, body=body, headers=headers)
  File "/usr/lib/python3.9/http/client.py", line 1285, in request
    self._send_request(method, url, body, headers, encode_chunked)
  File "/usr/lib/python3.9/http/client.py", line 1331, in _send_request
    self.endheaders(body, encode_chunked=encode_chunked)
  File "/usr/lib/python3.9/http/client.py", line 1280, in endheaders
    self._send_output(message_body, encode_chunked=encode_chunked)
  File "/usr/lib/python3.9/http/client.py", line 1040, in _send_output
    self.send(msg)
  File "/usr/lib/python3.9/http/client.py", line 980, in send
    self.connect()
  File "/usr/lib/python3.9/site-packages/urllib3/connection.py", line 205, in connect
    conn = self._new_conn()
  File "/usr/lib/python3.9/site-packages/urllib3/connection.py", line 186, in _new_conn
    raise NewConnectionError(
urllib3.exceptions.NewConnectionError: <urllib3.connection.HTTPConnection object at 0x7f8aa3bd90d0>: Failed to establish a new connection: [Errno 113] No route to host

During handling of the above exception, another exception occurred:

Traceback (most recent call last):
  File "/usr/lib/python3.9/site-packages/requests/adapters.py", line 667, in send
    resp = conn.urlopen(
  File "/usr/lib/python3.9/site-packages/urllib3/connectionpool.py", line 802, in urlopen
    retries = retries.increment(
  File "/usr/lib/python3.9/site-packages/urllib3/util/retry.py", line 594, in increment
    raise MaxRetryError(_pool, url, error or ResponseError(cause))
urllib3.exceptions.MaxRetryError: HTTPConnectionPool(host='192.168.200.254', port=5000): Max retries exceeded with url: /enforce (Caused by NewConnectionError('<urllib3.connection.HTTPConnection object at 0x7f8aa3bd90d0>: Failed to establish a new connection: [Errno 113] No route to host'))

During handling of the above exception, another exception occurred:

Traceback (most recent call last):
  File "/opt/splunk/etc/apps/my_custom_alerts/bin/scripts/policy_enforcer.py", line 53, in main
    response = requests.post(FLASK_URL, json=alert_data)
  File "/usr/lib/python3.9/site-packages/requests/api.py", line 115, in post
    return request("post", url, data=data, json=json, **kwargs)
  File "/usr/lib/python3.9/site-packages/requests/api.py", line 59, in request
    return session.request(method=method, url=url, **kwargs)
  File "/usr/lib/python3.9/site-packages/requests/sessions.py", line 589, in request
    resp = self.send(prep, **send_kwargs)
  File "/usr/lib/python3.9/site-packages/requests/sessions.py", line 703, in send
    r = adapter.send(request, **kwargs)
  File "/usr/lib/python3.9/site-packages/requests/adapters.py", line 700, in send
    raise ConnectionError(e, request=request)
requests.exceptions.ConnectionError: HTTPConnectionPool(host='192.168.200.254', port=5000): Max retries exceeded with url: /enforce (Caused by NewConnectionError('<urllib3.connection.HTTPConnection object at 0x7f8aa3bd90d0>: Failed to establish a new connection: [Errno 113] No route to host'))

2025-05-19T16:21:00.835453 - Script policy_enforcer.py avviato
2025-05-19T16:21:00.838737 - ❌ Errore di parsing JSON: Expecting value: line 1 column 1 (char 0)
2025-05-19T16:22:00.763509 - Script policy_enforcer.py avviato
2025-05-19T16:22:00.766669 - ❌ Errore di parsing JSON: Expecting value: line 1 column 1 (char 0)
2025-05-19T16:23:00.821866 - Script policy_enforcer.py avviato
2025-05-19T16:23:00.825615 - ❌ Errore di parsing JSON: Expecting value: line 1 column 1 (char 0)
2025-05-19T16:24:00.792541 - Script policy_enforcer.py avviato
2025-05-19T16:24:00.795648 - ❌ Errore di parsing JSON: Expecting value: line 1 column 1 (char 0)
2025-05-19T16:25:00.780783 - Script policy_enforcer.py avviato
2025-05-19T16:25:00.783865 - ❌ Errore di parsing JSON: Expecting value: line 1 column 1 (char 0)
2025-05-19T16:26:00.760572 - Script policy_enforcer.py avviato
2025-05-19T16:26:00.764160 - ❌ Errore di parsing JSON: Expecting value: line 1 column 1 (char 0)
2025-05-19T16:27:00.779188 - Script policy_enforcer.py avviato
2025-05-19T16:27:00.782787 - ❌ Errore di parsing JSON: Expecting value: line 1 column 1 (char 0)
2025-05-19T16:28:00.762864 - Script policy_enforcer.py avviato
2025-05-19T16:28:00.766222 - ❌ Errore di parsing JSON: Expecting value: line 1 column 1 (char 0)
2025-05-19T16:31:14.254313 - Script policy_enforcer.py avviato
2025-05-19T16:31:14.257771 - ❌ Errore di parsing JSON: Expecting value: line 1 column 1 (char 0)
2025-05-19T16:32:00.880195 - Script policy_enforcer.py avviato
2025-05-19T16:32:00.882417 - ❌ Errore di parsing JSON: Expecting value: line 1 column 1 (char 0)
2025-05-19T16:35:01.951492 - Script policy_enforcer.py avviato
2025-05-19T16:35:01.956557 - ❌ Errore di parsing JSON: Expecting value: line 1 column 1 (char 0)
2025-05-19T16:36:01.206665 - Script policy_enforcer.py avviato
2025-05-19T16:36:01.210025 - ❌ Errore di parsing JSON: Expecting value: line 1 column 1 (char 0)
2025-05-19T16:37:01.161253 - Script policy_enforcer.py avviato
2025-05-19T16:37:01.164828 - ❌ Errore di parsing JSON: Expecting value: line 1 column 1 (char 0)
2025-05-19T16:38:01.195411 - Script policy_enforcer.py avviato
2025-05-19T16:38:01.198513 - ❌ Errore di parsing JSON: Expecting value: line 1 column 1 (char 0)
2025-05-19T16:39:01.132125 - Script policy_enforcer.py avviato
2025-05-19T16:39:01.135341 - ❌ Errore di parsing JSON: Expecting value: line 1 column 1 (char 0)
2025-05-19T16:40:01.100224 - Script policy_enforcer.py avviato
2025-05-19T16:40:01.102656 - ❌ Errore di parsing JSON: Expecting value: line 1 column 1 (char 0)
2025-05-19T16:41:01.141826 - Script policy_enforcer.py avviato
2025-05-19T16:41:01.145080 - ❌ Errore di parsing JSON: Expecting value: line 1 column 1 (char 0)
2025-05-19T16:42:01.333581 - Script policy_enforcer.py avviato
2025-05-19T16:42:01.336041 - ❌ Errore di parsing JSON: Expecting value: line 1 column 1 (char 0)
2025-05-19T16:43:01.174290 - Script policy_enforcer.py avviato
2025-05-19T16:43:01.177492 - ❌ Errore di parsing JSON: Expecting value: line 1 column 1 (char 0)
2025-05-19T16:44:01.345532 - Script policy_enforcer.py avviato
2025-05-19T16:44:01.349215 - ❌ Errore di parsing JSON: Expecting value: line 1 column 1 (char 0)
2025-05-19T16:45:01.472038 - Script policy_enforcer.py avviato
2025-05-19T16:45:01.476293 - ❌ Errore di parsing JSON: Expecting value: line 1 column 1 (char 0)
2025-05-19T16:49:23.633250 - Script policy_enforcer.py avviato
2025-05-19T16:49:23.636511 - 📥 Payload grezzo da stdin:
'sessionKey=ePw%5EzV4AnYDAwEyA5LzijAOrmh0pZk38QbZ9BU2tenkYZOWogAgG28uiF8zEgJkGGQjoYxU7brMXAYcEjHzcz7bnR3pHqxoLefOQMGzk2erS%5EaGl8TX0XglGC5ed2H%5EB986DCxgADFIwNisV91UX6pZ7'
2025-05-19T16:49:23.639920 - ❌ Errore di parsing JSON: Expecting value: line 1 column 1 (char 0)
2025-05-19T16:50:01.360968 - Script policy_enforcer.py avviato
2025-05-19T16:50:01.364377 - 📥 Payload grezzo da stdin:
'sessionKey=n_cTYYQhGze2JamZDu3RKsH%5ER7RWo_d78ZnXa_2lDecavrd8nv1_Z%5EbJrYNaazq%5EEyr_IdgcW10SbvFLVhC_FVFp2NcAZpwxtYMsyJwuQ_PxnWjMIVTnS6LVBEDJQt%5EOg_4JwVuL8OY2TIbVkYJU3PL'
2025-05-19T16:50:01.369703 - ❌ Errore di parsing JSON: Expecting value: line 1 column 1 (char 0)
2025-05-19T16:51:01.252733 - Script policy_enforcer.py avviato
2025-05-19T16:51:01.255930 - 📥 Payload grezzo da stdin:
'sessionKey=jwOpHtkQhG5Q%5E%5E5PLbbarjZS1CUzWnx4WLA3ebyMbh%5Em8q9Qzc3Mp9%5EhOclL1szR2bsjKw7X_iW6UUkhgd5dGRvW84Sju4v0l14R5VYq6H7eEk9MBSdvNMbJ27FTkl8eokOa4D_fTomZt2wFgoa3pVyueHpw'
2025-05-19T16:51:01.258909 - ❌ Errore di parsing JSON: Expecting value: line 1 column 1 (char 0)
2025-05-19T16:52:01.270597 - Script policy_enforcer.py avviato
2025-05-19T16:52:01.273873 - 📥 Payload grezzo da stdin:
'sessionKey=hE7UlKR5YysCLUgBklbLo7ltAG_34cIJfLdU9H1t_XlpCdn_MwiMVGWVtvPzjLKJMTGL%5Evui4AiaTPUJ5rgGtUiG4UAAyCS1fkXS48wjSs2aa23IapX%5EHpwAXLEXGAwJwe_SCqbfPWwQDMultupsLF'
2025-05-19T16:52:01.276880 - ❌ Errore di parsing JSON: Expecting value: line 1 column 1 (char 0)
2025-05-19T16:53:01.223911 - Script policy_enforcer.py avviato
2025-05-19T16:53:01.226776 - 📥 Payload grezzo da stdin:
'sessionKey=xFjPu2PQn0fkEtXNxPuQX5ZlF9p_0%5E5YsOMuAT2p7q3XdJQT_cbZM_o7dvdxWy3%5EKUvAg%5EFGGJW6RmlibMTvouW9q3%5EpTUIPR8rZyhyYlegs7REym6iVwXZwkfiqpj65bae8cEhoGVc6Hce5%5EqJX_8TkUXa'
2025-05-19T16:53:01.229509 - ❌ Errore di parsing JSON: Expecting value: line 1 column 1 (char 0)
2025-05-19T16:54:01.259602 - Script policy_enforcer.py avviato
2025-05-19T16:54:01.262777 - 📥 Payload grezzo da stdin:
'sessionKey=BYSjCUD6pihigH0gS3jNLLvjXjFVTheEGcVncx1fcK%5EbOTOQA_r19wz6oh7niLhibKCfGsPUcH_mstOzkLyDZ8KPefhiKigMRk76euCEbWyEq62AAXhc_47PqGnjXryPKXCuoERdghe9lc0NwEJ9Uo'
2025-05-19T16:54:01.265879 - ❌ Errore di parsing JSON: Expecting value: line 1 column 1 (char 0)
2025-05-19T16:55:01.274019 - Script policy_enforcer.py avviato
2025-05-19T16:55:01.276340 - 📥 Payload grezzo da stdin:
'sessionKey=gSNJ6QiHpEo8Jy_Fi78l4vnJSxZ%5EArHLCQFGfrG8k9qUM_BaLC5hf5zb2Pyir5a8AsOUgHJb8xXgXIZLLV8lF861bgprddXa9SERpv%5EwcDqKlJHSSDnjKlHF4mDF7Hd_BikVzFxUL6nW7S8PSyAxdF'
2025-05-19T16:55:01.278688 - ❌ Errore di parsing JSON: Expecting value: line 1 column 1 (char 0)
2025-05-19T16:56:01.176956 - Script policy_enforcer.py avviato
2025-05-19T16:56:01.180047 - 📥 Payload grezzo da stdin:
'sessionKey=qFxY48XgiYKXdI5Yi0UtBKQ7i4niroAtKFSt3OgJnkIbFdKkTSW8J6xZ1K1mdKvIWNWDjJ%5Ep%5EX6H3FvkZvB51kBeq43o3HkYl9lrTgOyeRmENCn6_atLy2bmxRHg3v9BssqoLOqnEGNJqyF4buh%5EkVACgb7S3C'
2025-05-19T16:56:01.183045 - ❌ Errore di parsing JSON: Expecting value: line 1 column 1 (char 0)
2025-05-19T16:57:01.189386 - Script policy_enforcer.py avviato
2025-05-19T16:57:01.192431 - 📥 Payload grezzo da stdin:
'sessionKey=SSbusJcw3hvkAf80Dme9xHIhN0wEpo9yqDPG4AX_s0obdXNHB7Ck8d0ZYnCy5HfLP6E47tIzwmsmH92UepX3Ds0WnLWD2Z1ZI607br8mDR79K2pPXCY0z3s8zxwmJqiVaZwArqt0paA34ExXRC_liCX40O0'
2025-05-19T16:57:01.195429 - ❌ Errore di parsing JSON: Expecting value: line 1 column 1 (char 0)
2025-05-19T16:58:01.307556 - Script policy_enforcer.py avviato
2025-05-19T16:58:01.311330 - 📥 Payload grezzo da stdin:
'sessionKey=73NB5F1COrSeXqfg6%5E3y1M8n8jGgUEtVSiIieNbFIiBiZSLHujclZaCjs7sR0845c4eWH8isbGGavHi5AnEi5kiBTq6iTkZu%5EEyOTnRT501o6xwVuBvZXI3nOu2tydRg4lfyw6XIqS_4K9RqQQ6LqN'
2025-05-19T16:58:01.314863 - ❌ Errore di parsing JSON: Expecting value: line 1 column 1 (char 0)
2025-05-19T16:59:01.398214 - Script policy_enforcer.py avviato
2025-05-19T16:59:01.401915 - 📥 Payload grezzo da stdin:
'sessionKey=9Oi9uo35I1hJs0xcihTrUGDYPNYOA5WW0Pgipc5TUfBCsRX4Z8NK9OV4RjA774QSuZyDYaT4eDWIP11d_EXWKwxs%5E8RsFJoajzMEcbPw_VTJt%5E4FWpvqiuR7jAh0fVg8EDZDL3LYLQEhebPwSONzlrhrb2dm'
2025-05-19T16:59:01.405700 - ❌ Errore di parsing JSON: Expecting value: line 1 column 1 (char 0)
2025-05-19T17:00:01.185414 - Script policy_enforcer.py avviato
2025-05-19T17:00:01.188434 - 📥 Payload grezzo da stdin:
'sessionKey=OvaudA%5Ep_Ec4QPtj%5E9JdzNWvmEyGZFlt0y%5E3Nxwxe5y_IdcJTxe8WWEJTjiahE8LonOURe0D6mOGi_Esbz23wbNPIma91aQq09Ao7spbcmbq6awb2Mc5PflJem7usvkM9G%5ESsjlitOQ6jKbjxhFdYo'
2025-05-19T17:00:01.192311 - ❌ Errore di parsing JSON: Expecting value: line 1 column 1 (char 0)
2025-05-19T17:01:01.203414 - Script policy_enforcer.py avviato
2025-05-19T17:01:01.206463 - 📥 Payload grezzo da stdin:
'sessionKey=Uv_Y7hOBKCHdixragv%5E4sxXAZx7rqJN052s_P2%5EFfSsS2W2LE2jObKHNe6GACMlR7RxzXy5h2iuV2FKYru4lhZPRd%5EQmc5GLxJsMUSuirhJAAqE_bhuIa9LMYBVDh1vF_PzWeNSFSOEkSeJqdsSz_Kuvflu8'
2025-05-19T17:01:01.209492 - ❌ Errore di parsing JSON: Expecting value: line 1 column 1 (char 0)
2025-05-19T17:02:01.255719 - Script policy_enforcer.py avviato
2025-05-19T17:02:01.259307 - 📥 Payload grezzo da stdin:
'sessionKey=3Amr3QjNID66EGr55k4pmGn9WAb8lpqR8hnpIZIiV6wRHDQHhUkwszHmuzW1uWZqPvgKlevYLpe3SIO84IfKZIS3hZeWlC6auv0TCS%5EY9d4icMty2b7F%5Ek9MYFzNfAH5sn0JGo_pUfH0QQvKTKAkAxShNYL'
2025-05-19T17:02:01.262762 - ❌ Errore di parsing JSON: Expecting value: line 1 column 1 (char 0)
2025-05-19T17:03:01.139374 - Script policy_enforcer.py avviato
2025-05-19T17:03:01.142534 - 📥 Payload grezzo da stdin:
'sessionKey=2sxC5lSoPn%5EZtislN9_QdymX2fbxs595hImjRb%5EWYY50D7vrGHY0q8dW9u7%5EwejalVbSXs8gfDfzk_vPabkmvha01d%5E7xbi3k9j1TOSRYKaaTgUdZCMtLZfUAe5ZcdaNhwwY9DAK7QOowI9Ixye95N'
2025-05-19T17:03:01.145674 - ❌ Errore di parsing JSON: Expecting value: line 1 column 1 (char 0)
2025-05-19T17:04:01.315226 - Script policy_enforcer.py avviato
2025-05-19T17:04:01.318611 - 📥 Payload grezzo da stdin:
'sessionKey=iAoarwonTPhMOGEXtXsxP7PLrtW%5EVvw0qbsmwF0zT%5E37lwC10UfMNvr%5EnamSentadFLNOxCfJvh5ESNzPbMA_mBhFboEmXK68NMJdxOy9unW1BRVYxbVUV6X1hrw_53790t5blSgGkOLb4qZt0Xs%5EMiGlo'
2025-05-19T17:04:01.322131 - ❌ Errore di parsing JSON: Expecting value: line 1 column 1 (char 0)
2025-05-19T17:05:01.633202 - Script policy_enforcer.py avviato
2025-05-19T17:05:01.636997 - 📥 Payload grezzo da stdin:
'sessionKey=wqNGikS%5EL1A6fHv2Y9R6iaHExRI0HYirTcPzRFP6u6ARXu5qLXNEY%5EaZYM5y1VUlHgPtKZyxsIs8cSRfi1MWUG6eXJKAFco1%5EZrwBJ268FlJKMEifxE6SayiPVQDyXAPF9JSSsJhfmwzzJl78ruduUc99F'
2025-05-19T17:05:01.640477 - ❌ Errore di parsing JSON: Expecting value: line 1 column 1 (char 0)
2025-05-19T17:06:01.284906 - Script policy_enforcer.py avviato
2025-05-19T17:06:01.288433 - 📥 Payload grezzo da stdin:
'sessionKey=ZE5V70uYBgBHC6sewqBrh7zuGR83XkmFxAw8oUjOQfQukQBkKut23ya13KMJhtCu1HhV70fhvOIef79K543a5RzSHnEtIV1heYJForiyfoZnAOnINtz4M7cSAIEyiEF8kwfthWSechHjlXE2oWHBfM0r4YQD_L3'
2025-05-19T17:06:01.291400 - ❌ Errore di parsing JSON: Expecting value: line 1 column 1 (char 0)
2025-05-19T17:07:01.148528 - Script policy_enforcer.py avviato
2025-05-19T17:07:01.152219 - 📥 Payload grezzo da stdin:
'sessionKey=sqvEvtBLiMT1Ua5RYR4avAh8WzCsKKnwILZO%5EwW5z1JAn6hDmz_oJsQXzdyKtEEZ0B6iEZADBVIQt92uGyDqxNvUaJTMozGma3Ee2grj0rAgiZGT6JwsRkdkoaphfEZF%5EaRYFAlr_7w9x8BHZfpW7g9D'
2025-05-19T17:07:01.155005 - ❌ Errore di parsing JSON: Expecting value: line 1 column 1 (char 0)
2025-05-19T17:08:01.290624 - Script policy_enforcer.py avviato
2025-05-19T17:08:01.294094 - 📥 Payload grezzo da stdin:
'sessionKey=ybOqax8Dr43pksYGIeTwzyvozJ1DVM%5Ef4UuzG%5Ez8y79_dKkzT%5E66r86X9YlXYZylOM_L8_pzQ8WaLQYarWfIgRqFUxai_KUuQhhdXcKy1iT4psqZfUVN8W4uHD2Kr6SRfcovq3Z1yiJYGtuthhrGSjNEEqA'
2025-05-19T17:08:01.298036 - ❌ Errore di parsing JSON: Expecting value: line 1 column 1 (char 0)
2025-05-19T17:09:01.213329 - Script policy_enforcer.py avviato
2025-05-19T17:09:01.216889 - 📥 Payload grezzo da stdin:
'sessionKey=%5E_Tihm8y1EbpmvooSwIcWWwuKYnTYI2kusL4QvXDR0Ryw8DOyC9xtvGvOficrO6Rdf5YF3xPPOfXa6%5EtjV_GSQrAoG0ONg7p%5E9S0xps4lTItjHb%5EOMVdfIlKKQOn_t3%5E2E0Jb0fva7YV2GYGQs4vUunQEC'
2025-05-19T17:09:01.220555 - ❌ Errore di parsing JSON: Expecting value: line 1 column 1 (char 0)
2025-05-19T17:10:01.278116 - Script policy_enforcer.py avviato
2025-05-19T17:10:01.281118 - 📥 Payload grezzo da stdin:
'sessionKey=AcgkqDCPxcIXR3pzQpqUN71bANxPfl92fdo2oUos40F7%5EbURtRaMUWXSAVtYL%5EOv5VQyBKi%5EmIu0IdVsNaZuBlPtH2ONnIpJN6wJ%5EHgwI14LFNIsdGw0uJmYb7uWFvQT4ohhS74IhkO2qFYWbQnfj3Li0JzmoC'
2025-05-19T17:10:01.283277 - ❌ Errore di parsing JSON: Expecting value: line 1 column 1 (char 0)
2025-05-19T17:11:01.146779 - Script policy_enforcer.py avviato
2025-05-19T17:11:01.150384 - 📥 Payload grezzo da stdin:
'sessionKey=iRIV0fC7JKvqk%5EeykL0NvGlY9g_hdHbIgRlCXpmXEKrsm33W5UcfznevL7TBxdOSCUyrKfHcQcWADBNKQPfL4haoq0i_ibyW_Wg_DTmm6UOhfKxkklWXReCIbV1hyOH1Nd0bmnjFhuKUPFb%5ElllQ0KEBMo'
2025-05-19T17:11:01.153914 - ❌ Errore di parsing JSON: Expecting value: line 1 column 1 (char 0)
2025-05-19T17:12:01.143888 - Script policy_enforcer.py avviato
2025-05-19T17:12:01.147411 - 📥 Payload grezzo da stdin:
'sessionKey=qEliJv5XPcdea%5E3eTCbR0Wo00C3nOAYUxFjeQrJwWQhuCpDajVfr_OgQmKGciQwX_T2g3p1g%5EvwLfNMirBfuZ6aEbYh%5E7zeoHkuBEZQhXaA%5ENxw_t%5EmU1Zl73qfjYsiJVtFLrKQXFtgv2ywLPNppQWuTjfmVReR3'
2025-05-19T17:12:01.150646 - ❌ Errore di parsing JSON: Expecting value: line 1 column 1 (char 0)
2025-05-19T17:13:01.109647 - Script policy_enforcer.py avviato
2025-05-19T17:13:01.112920 - 📥 Payload grezzo da stdin:
'sessionKey=R4ARjSohaGrVD_J235ShZ7LDHVvbvAHn8%5EBDWUfqdshzu9mlFc9lpK_i4e7iFDJDfYw6oQYY7HB8G5BOPiCcfnWo00l3tRpsI%5EOCRg0WSCU9mL_Wh_63hKXRiwItiNxfLjuYnGade7ZvkJGimOnYaOIFrjSH'
2025-05-19T17:13:01.115814 - ❌ Errore di parsing JSON: Expecting value: line 1 column 1 (char 0)
2025-05-19T17:14:01.192887 - Script policy_enforcer.py avviato
2025-05-19T17:14:01.195434 - 📥 Payload grezzo da stdin:
'sessionKey=WOUuwIu_W3oextSlDo_KHQt_PiteXvaNbmk5dwFPzwjYSwnFXESDTdyNCQ7LPjmLrynOupn5CCV2f0ZR1OVNuLkcX_TrFPeZYlVYySGfMRho2pBFw73aoETumnCBIPpTvfooEZKdNcLLKD83Zqo7wOFeRsWxIlRX'
2025-05-19T17:14:01.197469 - ❌ Errore di parsing JSON: Expecting value: line 1 column 1 (char 0)
2025-05-19T17:15:01.102944 - Script policy_enforcer.py avviato
2025-05-19T17:15:01.105498 - 📥 Payload grezzo da stdin:
'sessionKey=nqWIyUBwsYgALNDNxWyprdIcDUUiEaHSAmi%5EcAN1cNK_zlqDo8bXzNkXkygrv5QVkFSmiGWCSDhCkI8CaEQ9wpK78XG09PXH3VKaiSAfR3%5Eg5rhBJel5QRHsEcSvpDLLrogrMZRB%5Ei2DdJUufW6eoCeR'
2025-05-19T17:15:01.107529 - ❌ Errore di parsing JSON: Expecting value: line 1 column 1 (char 0)
2025-05-19T17:16:01.270624 - Script policy_enforcer.py avviato
2025-05-19T17:16:01.274199 - 📥 Payload grezzo da stdin:
'sessionKey=cwsWPC7m_lDHBDX0hpxC_Iuwj4xUYEE6dVcgbV0Q8JgYKhQDAdofQ6sER8KRJq9UX12M4D5Qbhw9RuBa9HGNiZQC9nqQ8ImvIcnzeuAC7aogeB6lYI8S8flidj2nkzgny4fiYc0u%5EEtIZGBtedSOcFa'
2025-05-19T17:16:01.277172 - ❌ Errore di parsing JSON: Expecting value: line 1 column 1 (char 0)
2025-05-19T17:17:01.439467 - Script policy_enforcer.py avviato
2025-05-19T17:17:01.441870 - 📥 Payload grezzo da stdin:
'sessionKey=CsKh_2au%5EQGFyT87YyliMISf9W7u3%5ELl06kFc85zKRW9fBMWXjgO_2dhatix0iYIDIkC_j3FN%5EZQXbs3CaROZDDsmTnYE_nf8JnAJuBOyB8m7rbJkRGQQlger8xnSQL9AHQaLUqpXTovbBbjX8v_J3V7GixVj0o'
2025-05-19T17:17:01.445049 - ❌ Errore di parsing JSON: Expecting value: line 1 column 1 (char 0)
2025-05-19T17:18:01.200784 - Script policy_enforcer.py avviato
2025-05-19T17:18:01.204366 - 📥 Payload grezzo da stdin:
'sessionKey=VS3AdVlSJf6Z_So5Tgdq8NKBLRwHEeXcF87WjOxdRo3JH7mFCOo%5EYrNvQeoydDBYrh5qTPqrzMiytqazonXTfATRl0tLRh%5Eq0u8_Fdqvarkyn7Zd49CnPnPMTmroSs8waAL0Ctntza4ByaZLyF4FiZd9'
2025-05-19T17:18:01.208386 - ❌ Errore di parsing JSON: Expecting value: line 1 column 1 (char 0)
